<?xml version="1.0" ?>
<robot name="dobot">

    <!-- добавление цветов -->
    <material name="Black">
        <color rgba="0 0 0 1" />
    </material>
    <material name="White">
        <color rgba="1 1 1 1" />
    </material>
    
    
    
    <!--  -->
    <gazebo reference="base_link">
        <material>Gazebo/White</material>
    </gazebo>
    <gazebo reference="link_4">
        <material>Gazebo/Black</material>
    </gazebo>
    <gazebo reference="link_end">
        <material>Gazebo/Black</material>
    </gazebo>
    <gazebo reference="link_probe">
        <material>Gazebo/White</material>
    </gazebo>
    
    
    
    <!-- -->
    <gazebo>
         <plugin name="gazebo_ros_control" filename="libgazebo_ros_control.so">
            <robotNamespace>/</robotNamespace>
        </plugin>
    </gazebo>
    
    <gazebo reference="link_probe">
      <sensor name="link_probe_contact" type="contact">
        <alwaysOn>true</alwaysOn>
        <!--updateRate>10.0</updateRate-->
        <contact>
          <collision>link_4_fixed_joint_lump__link_probe_collision_collision_4</collision>
        </contact>
        <plugin filename="libgazebo_ros_bumper.so" name="link_probe_gazebo_ros_bumper_controller">
          <frameName>link_probe</frameName>
          <bumperTopicName>/dobot_contact/link_probe</bumperTopicName>
        </plugin>
      </sensor>
      <!--material>Gazebo/Red</material-->
    </gazebo>
  
  
  
    <link name="world" />
    
    <joint name="fixed" type="fixed">
        <parent link="world" />
        <child link="base_link" />
    </joint>
    
    
    
    <!--  -->
    <link name="base_link">
        <visual>
            <origin rpy="0 0 3.14159265" xyz="0 0 0" />
            <geometry>
                <mesh filename="package://dobot_description/meshes/base_link.STL" />
            </geometry>
            <material name="White" />
        </visual>
        <collision>
            <origin rpy="0 0 0" xyz="0 0 0" />
            <geometry>
                <mesh filename="package://dobot_description/meshes/base_link.STL" />
            </geometry>
        </collision>
        <inertial>
            <mass value="2.8" />
            <origin xyz="0 0 0" rpy="0 0 0" />
            <inertia ixx="0.03" iyy="0.03" izz="0.03" ixy="0.0" ixz="0.0" iyz="0.0" />
        </inertial>
    </link>
    
    
    
    <!--  -->
    <joint name="joint_1" type="revolute">
        <origin rpy="0 0 -1.570796325" xyz="0 0 0.024" />
        <parent link="base_link" />
        <child link="link_1" />
        <axis xyz="0 0 1" />
        <limit effort="150.0" lower="-1.5708" upper="1.5708" velocity="3.15" />
    </joint>
    
    <link name="link_1">
        <visual>
            <origin rpy="0 0 0" xyz="0 0 0" />
            <geometry>
                <mesh filename="package://dobot_description/meshes/link_1.dae" />
            </geometry>
            <!--material name="White" /-->
        </visual>
        <collision>
            <origin rpy="0 0 0" xyz="0 0 0" />
            <geometry>
                <mesh filename="package://dobot_description/meshes/link_1.dae" />
            </geometry>
        </collision>
        <inertial>
            <mass value="0.1" />
            <origin xyz="0 0 0" rpy="0 0 0" />
            <inertia ixx="0.03" iyy="0.03" izz="0.03" ixy="0.0" ixz="0.0" iyz="0.0" />
        </inertial>
    </link>
    
    
    
    <!--  -->
    <joint name="joint_2" type="revolute">
        <origin rpy="1.570796325 0 -1.570796325" xyz="-0.01175 0 0.114" />
        <parent link="link_1" />
        <child link="link_2" />
        <axis xyz="0 0 1" />
        <limit effort="150.0" lower="0" upper="1.48353" velocity="3.15" />
    </joint>
    
    <link name="link_2">
        <visual>
            <origin rpy="0 0 0" xyz="0 0 0" />
            <geometry>
                <mesh filename="package://dobot_description/meshes/link_2.dae" />
            </geometry>
            <!--material name="Black" /-->
        </visual>
        <collision>
            <origin rpy="0 0 0" xyz="0 0 0" />
            <geometry>
                <mesh filename="package://dobot_description/meshes/link_2.dae" />
            </geometry>
        </collision>
        <inertial>
            <mass value="0.1" />
            <origin xyz="0 0 0" rpy="0 0 0" />
            <inertia ixx="0.03" iyy="0.03" izz="0.03" ixy="0.0" ixz="0.0" iyz="0.0" />
        </inertial>
    </link>
    
    
    
    <!--  -->
    <joint name="joint_3" type="revolute">
        <origin rpy="0 3.14159265 0" xyz="0.02699 0.13228 -0.01175" />
        <parent link="link_2" />
        <child link="link_3" />
        <axis xyz="0 0 1" />
        <limit effort="150.0" lower="-0.174533" upper="1.5708" velocity="3.15" />
    </joint>
    
    <link name="link_3">
        <visual>
            <origin rpy="0 0 0" xyz="0 0 0" />
            <geometry>
                <mesh filename="package://dobot_description/meshes/link_3.dae" />
            </geometry>
            <!--material name="White" /-->
        </visual>
        <collision>
            <origin rpy="0 0 0" xyz="0 0 0" />
            <geometry>
                <mesh filename="package://dobot_description/meshes/link_3.dae" />
            </geometry>
        </collision>
        <inertial>
            <mass value="0.1" />
            <origin xyz="0 0 0" rpy="0 0 0" />
            <inertia ixx="0.03" iyy="0.03" izz="0.03" ixy="0.0" ixz="0.0" iyz="0.0" />
        </inertial>
    </link>
    
    
    
    <!--  -->
    <joint name="joint_4" type="revolute">
        <origin rpy="0 3.14159265 0" xyz="0.07431 -0.12684 0.0" />
        <parent link="link_3" />
        <child link="link_4" />
        <axis xyz="0 0 1" />
        <limit effort="150.0" lower="-1.5708" upper="1.5708" velocity="3.15" />
    </joint>
    
    <link name="link_4">
        <visual>
            <origin rpy="0 0 0" xyz="0 0 0" />
            <geometry>
                <mesh filename="package://dobot_description/meshes/link_4.STL" />
            </geometry>
            <material name="Black" />
        </visual>
        <collision>
            <origin rpy="0 0 0" xyz="0 0 0" />
            <geometry>
                <mesh filename="package://dobot_description/meshes/link_4.STL" />
            </geometry>
        </collision>
        <inertial>
            <mass value="0.1" />
            <origin xyz="0 0 0" rpy="0 0 0" />
            <inertia ixx="0.03" iyy="0.03" izz="0.03" ixy="0.0" ixz="0.0" iyz="0.0" />
        </inertial>
    </link>
    
    
    
    <!-- -->
    <joint name="joint_end" type="fixed">
        <origin rpy="0 0 0" xyz="0 0 0" />
        <parent link="link_4" />
        <child link="link_end" />
    </joint>
    
    <link name="link_end">
        <visual>
            <origin rpy="1.57 0 0" xyz="-0.056 0 0" />
            <geometry>
                <cylinder length="0.008" radius="0.016" />
            </geometry>
            <material name="Black" />
        </visual>
        <visual>
            <origin rpy="1.57 0 0" xyz="-0.056 -0.008 0" />
            <geometry>
                <cylinder length="0.024" radius="0.01" />
            </geometry>
            <material name="Black" />
        </visual>
        <visual>
            <origin rpy="1.57 0 0" xyz="-0.056 -0.008 0" />
            <geometry>
                <cylinder length="0.032" radius="0.006" />
            </geometry>
            <material name="Black" />
        </visual>
        <collision>
            <origin rpy="1.57 0 0" xyz="-0.056 0 0" />
            <geometry>
                <cylinder length="0.008" radius="0.016" />
            </geometry>
        </collision>
        <collision>
            <origin rpy="1.57 0 0" xyz="-0.056 -0.008 0" />
            <geometry>
                <cylinder length="0.024" radius="0.01" />
            </geometry>
        </collision>
        <collision>
            <origin rpy="1.57 0 0" xyz="-0.056 -0.008 0" />
            <geometry>
                <cylinder length="0.032" radius="0.006" />
            </geometry>
        </collision>
        <inertial>
            <mass value="0.1" />
            <origin xyz="0 0 0" rpy="0 0 0" />
            <inertia ixx="0.03" iyy="0.03" izz="0.03" ixy="0.0" ixz="0.0" iyz="0.0" />
        </inertial>
    </link>
    
    
    
    <!-- -->
    <joint name="joint_probe" type="fixed">
        <origin rpy="0 0 0" xyz="0 0 0" />
        <parent link="link_end" />
        <child link="link_probe" />
    </joint>
    
    <link name="link_probe">
        <visual>
            <origin rpy="1.57 0 0" xyz="-0.056 -0.016 0" />
            <geometry>
                <cylinder length="0.048" radius="0.004" />
            </geometry>
            <material name="White" />
        </visual>
        <collision name="link_probe_collision">
            <origin rpy="1.57 0 0" xyz="-0.056 -0.016 0" />
            <geometry>
                <cylinder length="0.048" radius="0.004" />
            </geometry>
        </collision>
        <inertial>
            <mass value="0.1" />
            <origin xyz="0 0 0" rpy="0 0 0" />
            <inertia ixx="0.03" iyy="0.03" izz="0.03" ixy="0.0" ixz="0.0" iyz="0.0" />
        </inertial>
    </link>
    
  
    
    <!-- -->
    <transmission name="trans_joint_1">
        <type>transmission_interface/SimpleTransmission</type>
        <joint name="joint_1">
            <hardwareInterface>hardware_interface/PositionJointInterface</hardwareInterface>
        </joint>
        <actuator name="joint_1_motor">
            <hardwareInterface>hardware_interface/PositionJointInterface</hardwareInterface>
            <mechanicalReduction>1</mechanicalReduction>
        </actuator>
    </transmission>
    <transmission name="trans_joint_2">
        <type>transmission_interface/SimpleTransmission</type>
        <joint name="joint_2">
            <hardwareInterface>hardware_interface/PositionJointInterface</hardwareInterface>
        </joint>
        <actuator name="joint_2_motor">
            <hardwareInterface>hardware_interface/PositionJointInterface</hardwareInterface>
            <mechanicalReduction>1</mechanicalReduction>
        </actuator>
    </transmission>
    <transmission name="trans_joint_3">
        <type>transmission_interface/SimpleTransmission</type>
        <joint name="joint_3">
            <hardwareInterface>hardware_interface/PositionJointInterface</hardwareInterface>
        </joint>
        <actuator name="joint_3_motor">
            <hardwareInterface>hardware_interface/PositionJointInterface</hardwareInterface>
            <mechanicalReduction>1</mechanicalReduction>
        </actuator>
    </transmission>
    <transmission name="trans_joint_4">
        <type>transmission_interface/SimpleTransmission</type>
        <joint name="joint_4">
            <hardwareInterface>hardware_interface/PositionJointInterface</hardwareInterface>
        </joint>
        <actuator name="joint_4_motor">
            <hardwareInterface>hardware_interface/PositionJointInterface</hardwareInterface>
            <mechanicalReduction>1</mechanicalReduction>
        </actuator>
    </transmission>
    
</robot>

